<?xml version="1.0"?>
<robot name="simple_arm" xmlns:xacro="http://ros.org/wiki/xacro">

<link name="world"/>
<joint name="world_to_base" type="fixed">
    <parent link="world"/>
    <child link="base_link"/>
    <origin xyz="-1 -1 0" rpy="0 0 0"/>
</joint>

<!-- Base Link -->
<link name="base_link">
    <visual>
        <geometry><box size="0.2 0.2 0.05"/></geometry>
        <origin xyz="0 0 0.025"/>
        <material name="gray"><color rgba="0.5 0.5 0.5 1"/></material>
    </visual>
</link>

<!-- Link1 -->
<link name="link1">
    <visual>
        <geometry><cylinder length="0.3" radius="0.02"/></geometry>
        <origin xyz="0 0 0.15" rpy="0 0 0"/>
        <material name="blue"><color rgba="0 0 1 1"/></material>
    </visual>
</link>

<joint name="joint1" type="revolute">
    <parent link="base_link"/>
    <child link="link1"/>
    <origin xyz="0 0 0.05" rpy="0 0 0"/>
    <axis xyz="0 0 1"/>
    <limit lower="-3.14" upper="3.14" effort="1.0" velocity="1.0"/>
</joint>

<!-- Link2 -->
<link name="link2">
    <visual>
        <geometry><cylinder length="0.3" radius="0.02"/></geometry>
        <origin xyz="0 0 0.15" rpy="0 0 0"/>
        <material name="green"><color rgba="0 1 0 1"/></material>
    </visual>
</link>

<joint name="joint2" type="revolute">
    <parent link="link1"/>
    <child link="link2"/>
    <origin xyz="0 0 0.3" rpy="0 0 0"/>
    <axis xyz="0 1 0"/>
    <limit lower="-3.14" upper="3.14" effort="1.0" velocity="1.0"/>
</joint>

<!-- Camera -->
<link name="camera_link">
    <visual>
        <geometry><box size="0.05 0.05 0.05"/></geometry>
        <origin xyz="0 0 0.025"/>
        <material name="red"><color rgba="1 0 0 1"/></material>
    </visual>
</link>

<joint name="camera_joint" type="fixed">
    <parent link="link2"/>
    <child link="camera_link"/>
    <origin xyz="0 0 0.3" rpy="0 0 0"/>
</joint>

</robot>
